{"trial_id": "0001", "hyperparameters": {"space": [{"class_name": "Choice", "config": {"name": "activation", "default": "relu", "conditions": [], "values": ["relu", "tanh"], "ordered": false}}, {"class_name": "Choice", "config": {"name": "learning_rate", "default": 0.001, "conditions": [], "values": [0.001, 0.0001], "ordered": true}}, {"class_name": "Choice", "config": {"name": "filters", "default": 32, "conditions": [], "values": [32, 64], "ordered": true}}, {"class_name": "Choice", "config": {"name": "kernel_size", "default": 3, "conditions": [], "values": [3, 5], "ordered": true}}, {"class_name": "Choice", "config": {"name": "dense_units", "default": 64, "conditions": [], "values": [64, 128, 256], "ordered": true}}, {"class_name": "Int", "config": {"name": "layers", "default": null, "conditions": [], "min_value": 2, "max_value": 6, "step": 1, "sampling": "linear"}}], "values": {"activation": "relu", "learning_rate": 0.001, "filters": 32, "kernel_size": 5, "dense_units": 256, "layers": 2, "tuner/epochs": 2, "tuner/initial_epoch": 0, "tuner/bracket": 1, "tuner/round": 0}}, "metrics": {"metrics": {}}, "score": null, "best_step": 0, "status": "FAILED", "message": "Traceback (most recent call last):\n  File \"/home/roderickperez/.local/lib/python3.10/site-packages/keras_tuner/engine/base_tuner.py\", line 270, in _try_run_and_update_trial\n    self._run_and_update_trial(trial, *fit_args, **fit_kwargs)\n  File \"/home/roderickperez/.local/lib/python3.10/site-packages/keras_tuner/engine/base_tuner.py\", line 235, in _run_and_update_trial\n    results = self.run_trial(trial, *fit_args, **fit_kwargs)\n  File \"/home/roderickperez/.local/lib/python3.10/site-packages/keras_tuner/tuners/hyperband.py\", line 425, in run_trial\n    return super().run_trial(trial, *fit_args, **fit_kwargs)\n  File \"/home/roderickperez/.local/lib/python3.10/site-packages/keras_tuner/engine/tuner.py\", line 287, in run_trial\n    obj_value = self._build_and_fit_model(trial, *args, **copied_kwargs)\n  File \"/home/roderickperez/.local/lib/python3.10/site-packages/keras_tuner/engine/tuner.py\", line 214, in _build_and_fit_model\n    results = self.hypermodel.fit(hp, model, *args, **kwargs)\n  File \"/home/roderickperez/.local/lib/python3.10/site-packages/keras_tuner/engine/hypermodel.py\", line 144, in fit\n    return model.fit(*args, **kwargs)\n  File \"/usr/lib/python3/dist-packages/keras/utils/traceback_utils.py\", line 70, in error_handler\n    raise e.with_traceback(filtered_tb) from None\n  File \"/tmp/__autograph_generated_filevhzlhbb5.py\", line 15, in tf__train_function\n    retval_ = ag__.converted_call(ag__.ld(step_function), (ag__.ld(self), ag__.ld(iterator)), None, fscope)\nValueError: in user code:\n\n    File \"/usr/lib/python3/dist-packages/keras/engine/training.py\", line 1338, in train_function  *\n        return step_function(self, iterator)\n    File \"/usr/lib/python3/dist-packages/keras/engine/training.py\", line 1322, in step_function  **\n        outputs = model.distribute_strategy.run(run_step, args=(data,))\n    File \"/usr/lib/python3/dist-packages/keras/engine/training.py\", line 1303, in run_step  **\n        outputs = model.train_step(data)\n    File \"/usr/lib/python3/dist-packages/keras/engine/training.py\", line 1080, in train_step\n        y_pred = self(x, training=True)\n    File \"/usr/lib/python3/dist-packages/keras/utils/traceback_utils.py\", line 70, in error_handler\n        raise e.with_traceback(filtered_tb) from None\n    File \"/usr/lib/python3/dist-packages/keras/engine/input_spec.py\", line 253, in assert_input_compatibility\n        raise ValueError(\n\n    ValueError: Exception encountered when calling layer 'sequential' (type Sequential).\n    \n    Input 0 of layer \"conv2d\" is incompatible with the layer: expected min_ndim=4, found ndim=3. Full shape received: (32, 28, 28)\n    \n    Call arguments received by layer 'sequential' (type Sequential):\n      \u2022 inputs=tf.Tensor(shape=(32, 28, 28), dtype=float32)\n      \u2022 training=True\n      \u2022 mask=None\n\n"}